[2023-06-01T20:58:32.300+0000] {taskinstance.py:1087} INFO - Dependencies all met for <TaskInstance: etl_pj_br.DADOS_DEV.extract_data manual__2023-06-01T20:58:29.230427+00:00 [queued]>
[2023-06-01T20:58:32.319+0000] {taskinstance.py:1087} INFO - Dependencies all met for <TaskInstance: etl_pj_br.DADOS_DEV.extract_data manual__2023-06-01T20:58:29.230427+00:00 [queued]>
[2023-06-01T20:58:32.320+0000] {taskinstance.py:1283} INFO - 
--------------------------------------------------------------------------------
[2023-06-01T20:58:32.320+0000] {taskinstance.py:1284} INFO - Starting attempt 1 of 1
[2023-06-01T20:58:32.320+0000] {taskinstance.py:1285} INFO - 
--------------------------------------------------------------------------------
[2023-06-01T20:58:32.342+0000] {taskinstance.py:1304} INFO - Executing <Task(PythonOperator): DADOS_DEV.extract_data> on 2023-06-01 20:58:29.230427+00:00
[2023-06-01T20:58:32.349+0000] {standard_task_runner.py:55} INFO - Started process 6096 to run task
[2023-06-01T20:58:32.353+0000] {standard_task_runner.py:82} INFO - Running: ['***', 'tasks', 'run', 'etl_pj_br', 'DADOS_DEV.extract_data', 'manual__2023-06-01T20:58:29.230427+00:00', '--job-id', '80', '--raw', '--subdir', 'DAGS_FOLDER/pip_example.py', '--cfg-path', '/tmp/tmpn42ubkze']
[2023-06-01T20:58:32.355+0000] {standard_task_runner.py:83} INFO - Job 80: Subtask DADOS_DEV.extract_data
[2023-06-01T20:58:32.426+0000] {task_command.py:389} INFO - Running <TaskInstance: etl_pj_br.DADOS_DEV.extract_data manual__2023-06-01T20:58:29.230427+00:00 [running]> on host e77927a9666c
[2023-06-01T20:58:32.558+0000] {taskinstance.py:1513} INFO - Exporting the following env vars:
AIRFLOW_CTX_DAG_OWNER=***
AIRFLOW_CTX_DAG_ID=etl_pj_br
AIRFLOW_CTX_TASK_ID=DADOS_DEV.extract_data
AIRFLOW_CTX_EXECUTION_DATE=2023-06-01T20:58:29.230427+00:00
AIRFLOW_CTX_TRY_NUMBER=1
AIRFLOW_CTX_DAG_RUN_ID=manual__2023-06-01T20:58:29.230427+00:00
[2023-06-01T20:58:32.559+0000] {taskinstance.py:1772} ERROR - Task failed with exception
Traceback (most recent call last):
  File "/home/airflow/.local/lib/python3.7/site-packages/airflow/operators/python.py", line 172, in execute
    context_merge(context, self.op_kwargs, templates_dict=self.templates_dict)
  File "/home/airflow/.local/lib/python3.7/site-packages/airflow/utils/context.py", line 259, in context_merge
    context.update(*args, **kwargs)
  File "/usr/local/lib/python3.7/_collections_abc.py", line 846, in update
    for key, value in other:
ValueError: too many values to unpack (expected 2)
[2023-06-01T20:58:32.575+0000] {taskinstance.py:1327} INFO - Marking task as FAILED. dag_id=etl_pj_br, task_id=DADOS_DEV.extract_data, execution_date=20230601T205829, start_date=20230601T205832, end_date=20230601T205832
[2023-06-01T20:58:32.596+0000] {standard_task_runner.py:105} ERROR - Failed to execute job 80 for task DADOS_DEV.extract_data (too many values to unpack (expected 2); 6096)
[2023-06-01T20:58:32.645+0000] {local_task_job.py:159} INFO - Task exited with return code 1
[2023-06-01T20:58:32.698+0000] {taskinstance.py:2582} INFO - 0 downstream tasks scheduled from follow-on schedule check
