[2023-06-01T20:47:49.980+0000] {taskinstance.py:1087} INFO - Dependencies all met for <TaskInstance: etl_pj_br.DADOS_GOV.extract_data manual__2023-06-01T20:47:45.897899+00:00 [queued]>
[2023-06-01T20:47:49.998+0000] {taskinstance.py:1087} INFO - Dependencies all met for <TaskInstance: etl_pj_br.DADOS_GOV.extract_data manual__2023-06-01T20:47:45.897899+00:00 [queued]>
[2023-06-01T20:47:49.998+0000] {taskinstance.py:1283} INFO - 
--------------------------------------------------------------------------------
[2023-06-01T20:47:49.998+0000] {taskinstance.py:1284} INFO - Starting attempt 1 of 1
[2023-06-01T20:47:49.998+0000] {taskinstance.py:1285} INFO - 
--------------------------------------------------------------------------------
[2023-06-01T20:47:50.020+0000] {taskinstance.py:1304} INFO - Executing <Task(PythonOperator): DADOS_GOV.extract_data> on 2023-06-01 20:47:45.897899+00:00
[2023-06-01T20:47:50.029+0000] {standard_task_runner.py:55} INFO - Started process 5232 to run task
[2023-06-01T20:47:50.032+0000] {standard_task_runner.py:82} INFO - Running: ['***', 'tasks', 'run', 'etl_pj_br', 'DADOS_GOV.extract_data', 'manual__2023-06-01T20:47:45.897899+00:00', '--job-id', '75', '--raw', '--subdir', 'DAGS_FOLDER/pip_example.py', '--cfg-path', '/tmp/tmpktmjafib']
[2023-06-01T20:47:50.033+0000] {standard_task_runner.py:83} INFO - Job 75: Subtask DADOS_GOV.extract_data
[2023-06-01T20:47:50.090+0000] {task_command.py:389} INFO - Running <TaskInstance: etl_pj_br.DADOS_GOV.extract_data manual__2023-06-01T20:47:45.897899+00:00 [running]> on host e77927a9666c
[2023-06-01T20:47:50.170+0000] {taskinstance.py:1513} INFO - Exporting the following env vars:
AIRFLOW_CTX_DAG_OWNER=***
AIRFLOW_CTX_DAG_ID=etl_pj_br
AIRFLOW_CTX_TASK_ID=DADOS_GOV.extract_data
AIRFLOW_CTX_EXECUTION_DATE=2023-06-01T20:47:45.897899+00:00
AIRFLOW_CTX_TRY_NUMBER=1
AIRFLOW_CTX_DAG_RUN_ID=manual__2023-06-01T20:47:45.897899+00:00
[2023-06-01T20:47:50.172+0000] {taskinstance.py:1772} ERROR - Task failed with exception
Traceback (most recent call last):
  File "/home/airflow/.local/lib/python3.7/site-packages/airflow/operators/python.py", line 172, in execute
    context_merge(context, self.op_kwargs, templates_dict=self.templates_dict)
  File "/home/airflow/.local/lib/python3.7/site-packages/airflow/utils/context.py", line 259, in context_merge
    context.update(*args, **kwargs)
  File "/usr/local/lib/python3.7/_collections_abc.py", line 846, in update
    for key, value in other:
ValueError: too many values to unpack (expected 2)
[2023-06-01T20:47:50.185+0000] {taskinstance.py:1327} INFO - Marking task as FAILED. dag_id=etl_pj_br, task_id=DADOS_GOV.extract_data, execution_date=20230601T204745, start_date=20230601T204749, end_date=20230601T204750
[2023-06-01T20:47:50.200+0000] {standard_task_runner.py:105} ERROR - Failed to execute job 75 for task DADOS_GOV.extract_data (too many values to unpack (expected 2); 5232)
[2023-06-01T20:47:50.246+0000] {local_task_job.py:159} INFO - Task exited with return code 1
[2023-06-01T20:47:50.275+0000] {taskinstance.py:2582} INFO - 0 downstream tasks scheduled from follow-on schedule check
