[2023-06-01T20:50:50.918+0000] {taskinstance.py:1087} INFO - Dependencies all met for <TaskInstance: etl_pj_br.DADOS_GOV.extract_data manual__2023-06-01T20:50:48.616038+00:00 [queued]>
[2023-06-01T20:50:50.934+0000] {taskinstance.py:1087} INFO - Dependencies all met for <TaskInstance: etl_pj_br.DADOS_GOV.extract_data manual__2023-06-01T20:50:48.616038+00:00 [queued]>
[2023-06-01T20:50:50.935+0000] {taskinstance.py:1283} INFO - 
--------------------------------------------------------------------------------
[2023-06-01T20:50:50.935+0000] {taskinstance.py:1284} INFO - Starting attempt 1 of 1
[2023-06-01T20:50:50.935+0000] {taskinstance.py:1285} INFO - 
--------------------------------------------------------------------------------
[2023-06-01T20:50:50.964+0000] {taskinstance.py:1304} INFO - Executing <Task(PythonOperator): DADOS_GOV.extract_data> on 2023-06-01 20:50:48.616038+00:00
[2023-06-01T20:50:50.975+0000] {standard_task_runner.py:55} INFO - Started process 5477 to run task
[2023-06-01T20:50:50.981+0000] {standard_task_runner.py:82} INFO - Running: ['***', 'tasks', 'run', 'etl_pj_br', 'DADOS_GOV.extract_data', 'manual__2023-06-01T20:50:48.616038+00:00', '--job-id', '77', '--raw', '--subdir', 'DAGS_FOLDER/pip_example.py', '--cfg-path', '/tmp/tmpq2whp76r']
[2023-06-01T20:50:50.984+0000] {standard_task_runner.py:83} INFO - Job 77: Subtask DADOS_GOV.extract_data
[2023-06-01T20:50:51.070+0000] {task_command.py:389} INFO - Running <TaskInstance: etl_pj_br.DADOS_GOV.extract_data manual__2023-06-01T20:50:48.616038+00:00 [running]> on host e77927a9666c
[2023-06-01T20:50:51.161+0000] {taskinstance.py:1513} INFO - Exporting the following env vars:
AIRFLOW_CTX_DAG_OWNER=***
AIRFLOW_CTX_DAG_ID=etl_pj_br
AIRFLOW_CTX_TASK_ID=DADOS_GOV.extract_data
AIRFLOW_CTX_EXECUTION_DATE=2023-06-01T20:50:48.616038+00:00
AIRFLOW_CTX_TRY_NUMBER=1
AIRFLOW_CTX_DAG_RUN_ID=manual__2023-06-01T20:50:48.616038+00:00
[2023-06-01T20:50:51.162+0000] {taskinstance.py:1772} ERROR - Task failed with exception
Traceback (most recent call last):
  File "/home/airflow/.local/lib/python3.7/site-packages/airflow/operators/python.py", line 172, in execute
    context_merge(context, self.op_kwargs, templates_dict=self.templates_dict)
  File "/home/airflow/.local/lib/python3.7/site-packages/airflow/utils/context.py", line 259, in context_merge
    context.update(*args, **kwargs)
  File "/usr/local/lib/python3.7/_collections_abc.py", line 846, in update
    for key, value in other:
ValueError: too many values to unpack (expected 2)
[2023-06-01T20:50:51.171+0000] {taskinstance.py:1327} INFO - Marking task as FAILED. dag_id=etl_pj_br, task_id=DADOS_GOV.extract_data, execution_date=20230601T205048, start_date=20230601T205050, end_date=20230601T205051
[2023-06-01T20:50:51.184+0000] {standard_task_runner.py:105} ERROR - Failed to execute job 77 for task DADOS_GOV.extract_data (too many values to unpack (expected 2); 5477)
[2023-06-01T20:50:51.232+0000] {local_task_job.py:159} INFO - Task exited with return code 1
[2023-06-01T20:50:51.269+0000] {taskinstance.py:2582} INFO - 0 downstream tasks scheduled from follow-on schedule check
